[2023-05-07 21:32:34,270] {taskinstance.py:1159} INFO - Dependencies all met for <TaskInstance: riskthinking_ai_de.download_data manual__2023-05-07T21:32:26.387155+00:00 [queued]>
[2023-05-07 21:32:34,291] {taskinstance.py:1159} INFO - Dependencies all met for <TaskInstance: riskthinking_ai_de.download_data manual__2023-05-07T21:32:26.387155+00:00 [queued]>
[2023-05-07 21:32:34,292] {taskinstance.py:1356} INFO - 
--------------------------------------------------------------------------------
[2023-05-07 21:32:34,293] {taskinstance.py:1357} INFO - Starting attempt 1 of 1
[2023-05-07 21:32:34,294] {taskinstance.py:1358} INFO - 
--------------------------------------------------------------------------------
[2023-05-07 21:32:34,322] {taskinstance.py:1377} INFO - Executing <Task(_PythonDecoratedOperator): download_data> on 2023-05-07 21:32:26.387155+00:00
[2023-05-07 21:32:34,336] {standard_task_runner.py:52} INFO - Started process 12381 to run task
[2023-05-07 21:32:34,343] {standard_task_runner.py:79} INFO - Running: ['***', 'tasks', 'run', 'riskthinking_ai_de', 'download_data', 'manual__2023-05-07T21:32:26.387155+00:00', '--job-id', '279', '--raw', '--subdir', 'DAGS_FOLDER/files/rt_ai_etl.py', '--cfg-path', '/tmp/tmpb5cx_6y9', '--error-file', '/tmp/tmp5h7krugh']
[2023-05-07 21:32:34,347] {standard_task_runner.py:80} INFO - Job 279: Subtask download_data
[2023-05-07 21:32:34,440] {task_command.py:369} INFO - Running <TaskInstance: riskthinking_ai_de.download_data manual__2023-05-07T21:32:26.387155+00:00 [running]> on host 16ca7fe0df6c
[2023-05-07 21:32:34,590] {taskinstance.py:1571} INFO - Exporting the following env vars:
AIRFLOW_CTX_DAG_OWNER=***
AIRFLOW_CTX_DAG_ID=riskthinking_ai_de
AIRFLOW_CTX_TASK_ID=download_data
AIRFLOW_CTX_EXECUTION_DATE=2023-05-07T21:32:26.387155+00:00
AIRFLOW_CTX_TRY_NUMBER=1
AIRFLOW_CTX_DAG_RUN_ID=manual__2023-05-07T21:32:26.387155+00:00
[2023-05-07 21:32:34,593] {logging_mixin.py:115} INFO - Downloading data for A
[2023-05-07 21:32:34,596] {logging_mixin.py:115} INFO - Failed to create TzCache, reason: Error creating TzCache folder: '/home/***/.cache/py-yfinance' reason: [Errno 13] Permission denied: '/home/***/.cache/py-yfinance'
[2023-05-07 21:32:34,597] {logging_mixin.py:115} INFO - TzCache will not be used.
[2023-05-07 21:32:34,598] {logging_mixin.py:115} INFO - Tip: You can direct cache to use a different location with 'set_tz_cache_location(mylocation)'
[2023-05-07 21:32:35,166] {logging_mixin.py:115} INFO - [*********************100%***********************]  1 of 1 completed
[2023-05-07 21:32:35,170] {logging_mixin.py:115} INFO - Downloading data for AA
[2023-05-07 21:32:35,797] {logging_mixin.py:115} INFO - [*********************100%***********************]  1 of 1 completed
[2023-05-07 21:32:35,801] {logging_mixin.py:115} INFO - Downloading data for AAAU
[2023-05-07 21:32:36,252] {logging_mixin.py:115} INFO - [*********************100%***********************]  1 of 1 completed
[2023-05-07 21:32:36,258] {logging_mixin.py:115} INFO - Downloading data for AADR
[2023-05-07 21:32:36,795] {logging_mixin.py:115} INFO - [*********************100%***********************]  1 of 1 completed
[2023-05-07 21:32:36,984] {logging_mixin.py:115} INFO - processed 328 rows
[2023-05-07 21:32:36,985] {python.py:173} INFO - Done. Returned value was: yfinance_data.parquet
[2023-05-07 21:32:37,028] {taskinstance.py:1400} INFO - Marking task as SUCCESS. dag_id=riskthinking_ai_de, task_id=download_data, execution_date=20230507T213226, start_date=20230507T213234, end_date=20230507T213237
[2023-05-07 21:32:37,091] {local_task_job.py:156} INFO - Task exited with return code 0
[2023-05-07 21:32:37,173] {local_task_job.py:273} INFO - 1 downstream tasks scheduled from follow-on schedule check
